[2025-04-18T17:14:15.934+0000] {local_task_job_runner.py:123} INFO - ::group::Pre task execution logs
[2025-04-18T17:14:15.960+0000] {taskinstance.py:2614} INFO - Dependencies all met for dep_context=non-requeueable deps ti=<TaskInstance: transaction_dag.get_data_task manual__2025-04-18T17:14:13.956810+00:00 [queued]>
[2025-04-18T17:14:15.970+0000] {taskinstance.py:2614} INFO - Dependencies all met for dep_context=requeueable deps ti=<TaskInstance: transaction_dag.get_data_task manual__2025-04-18T17:14:13.956810+00:00 [queued]>
[2025-04-18T17:14:15.970+0000] {taskinstance.py:2867} INFO - Starting attempt 1 of 1
[2025-04-18T17:14:15.984+0000] {taskinstance.py:2890} INFO - Executing <Task(PythonOperator): get_data_task> on 2025-04-18 17:14:13.956810+00:00
[2025-04-18T17:14:15.993+0000] {warnings.py:112} WARNING - /home/***/.local/lib/python3.12/site-packages/***/task/task_runner/standard_task_runner.py:70: DeprecationWarning: This process (pid=261) is multi-threaded, use of fork() may lead to deadlocks in the child.
  pid = os.fork()

[2025-04-18T17:14:15.995+0000] {standard_task_runner.py:72} INFO - Started process 262 to run task
[2025-04-18T17:14:15.995+0000] {standard_task_runner.py:104} INFO - Running: ['***', 'tasks', 'run', 'transaction_dag', 'get_data_task', 'manual__2025-04-18T17:14:13.956810+00:00', '--job-id', '6', '--raw', '--subdir', 'DAGS_FOLDER/transaction_dag.py', '--cfg-path', '/tmp/tmp0_95xi_k']
[2025-04-18T17:14:15.996+0000] {standard_task_runner.py:105} INFO - Job 6: Subtask get_data_task
[2025-04-18T17:14:16.045+0000] {task_command.py:467} INFO - Running <TaskInstance: transaction_dag.get_data_task manual__2025-04-18T17:14:13.956810+00:00 [running]> on host 317bb80a77ef
[2025-04-18T17:14:16.133+0000] {taskinstance.py:3134} INFO - Exporting env vars: AIRFLOW_CTX_DAG_OWNER='***' AIRFLOW_CTX_DAG_ID='transaction_dag' AIRFLOW_CTX_TASK_ID='get_data_task' AIRFLOW_CTX_EXECUTION_DATE='2025-04-18T17:14:13.956810+00:00' AIRFLOW_CTX_TRY_NUMBER='1' AIRFLOW_CTX_DAG_RUN_ID='manual__2025-04-18T17:14:13.956810+00:00'
[2025-04-18T17:14:16.134+0000] {taskinstance.py:732} INFO - ::endgroup::
[2025-04-18T17:14:16.169+0000] {taskinstance.py:3313} ERROR - Task failed with exception
Traceback (most recent call last):
  File "/home/airflow/.local/lib/python3.12/site-packages/airflow/models/taskinstance.py", line 768, in _execute_task
    result = _execute_callable(context=context, **execute_callable_kwargs)
             ^^^^^^^^^^^^^^^^^^^^^^^^^^^^^^^^^^^^^^^^^^^^^^^^^^^^^^^^^^^^^
  File "/home/airflow/.local/lib/python3.12/site-packages/airflow/models/taskinstance.py", line 734, in _execute_callable
    return ExecutionCallableRunner(
           ^^^^^^^^^^^^^^^^^^^^^^^^
  File "/home/airflow/.local/lib/python3.12/site-packages/airflow/utils/operator_helpers.py", line 252, in run
    return self.func(*args, **kwargs)
           ^^^^^^^^^^^^^^^^^^^^^^^^^^
  File "/home/airflow/.local/lib/python3.12/site-packages/airflow/models/baseoperator.py", line 424, in wrapper
    return func(self, *args, **kwargs)
           ^^^^^^^^^^^^^^^^^^^^^^^^^^^
  File "/home/airflow/.local/lib/python3.12/site-packages/airflow/operators/python.py", line 238, in execute
    return_value = self.execute_callable()
                   ^^^^^^^^^^^^^^^^^^^^^^^
  File "/home/airflow/.local/lib/python3.12/site-packages/airflow/operators/python.py", line 256, in execute_callable
    return runner.run(*self.op_args, **self.op_kwargs)
           ^^^^^^^^^^^^^^^^^^^^^^^^^^^^^^^^^^^^^^^^^^^
  File "/home/airflow/.local/lib/python3.12/site-packages/airflow/utils/operator_helpers.py", line 252, in run
    return self.func(*args, **kwargs)
           ^^^^^^^^^^^^^^^^^^^^^^^^^^
  File "/opt/airflow/dags/utils/ingest_data.py", line 37, in get_data
    conn = pg_connection()
           ^^^^^^^^^^^^^^^
  File "/opt/airflow/dags/utils/ingest_data.py", line 9, in pg_connection
    pg_user = Variable.get("PG_USER")
              ^^^^^^^^^^^^^^^^^^^^^^^
  File "/home/airflow/.local/lib/python3.12/site-packages/airflow/models/variable.py", line 145, in get
    raise KeyError(f"Variable {key} does not exist")
KeyError: 'Variable PG_USER does not exist'
[2025-04-18T17:14:16.181+0000] {taskinstance.py:1226} INFO - Marking task as FAILED. dag_id=transaction_dag, task_id=get_data_task, run_id=manual__2025-04-18T17:14:13.956810+00:00, execution_date=20250418T171413, start_date=20250418T171415, end_date=20250418T171416
[2025-04-18T17:14:16.209+0000] {taskinstance.py:341} INFO - ::group::Post task execution logs
[2025-04-18T17:14:16.210+0000] {standard_task_runner.py:124} ERROR - Failed to execute job 6 for task get_data_task ('Variable PG_USER does not exist'; 262)
Traceback (most recent call last):
  File "/home/airflow/.local/lib/python3.12/site-packages/airflow/task/task_runner/standard_task_runner.py", line 117, in _start_by_fork
    ret = args.func(args, dag=self.dag)
          ^^^^^^^^^^^^^^^^^^^^^^^^^^^^^
  File "/home/airflow/.local/lib/python3.12/site-packages/airflow/cli/cli_config.py", line 49, in command
    return func(*args, **kwargs)
           ^^^^^^^^^^^^^^^^^^^^^
  File "/home/airflow/.local/lib/python3.12/site-packages/airflow/utils/cli.py", line 116, in wrapper
    return f(*args, **kwargs)
           ^^^^^^^^^^^^^^^^^^
  File "/home/airflow/.local/lib/python3.12/site-packages/airflow/cli/commands/task_command.py", line 483, in task_run
    task_return_code = _run_task_by_selected_method(args, _dag, ti)
                       ^^^^^^^^^^^^^^^^^^^^^^^^^^^^^^^^^^^^^^^^^^^^
  File "/home/airflow/.local/lib/python3.12/site-packages/airflow/cli/commands/task_command.py", line 256, in _run_task_by_selected_method
    return _run_raw_task(args, ti)
           ^^^^^^^^^^^^^^^^^^^^^^^
  File "/home/airflow/.local/lib/python3.12/site-packages/airflow/cli/commands/task_command.py", line 341, in _run_raw_task
    return ti._run_raw_task(
           ^^^^^^^^^^^^^^^^^
  File "/home/airflow/.local/lib/python3.12/site-packages/airflow/utils/session.py", line 97, in wrapper
    return func(*args, session=session, **kwargs)
           ^^^^^^^^^^^^^^^^^^^^^^^^^^^^^^^^^^^^^^
  File "/home/airflow/.local/lib/python3.12/site-packages/airflow/models/taskinstance.py", line 3006, in _run_raw_task
    return _run_raw_task(
           ^^^^^^^^^^^^^^
  File "/home/airflow/.local/lib/python3.12/site-packages/airflow/models/taskinstance.py", line 274, in _run_raw_task
    TaskInstance._execute_task_with_callbacks(
  File "/home/airflow/.local/lib/python3.12/site-packages/airflow/models/taskinstance.py", line 3161, in _execute_task_with_callbacks
    result = self._execute_task(context, task_orig)
             ^^^^^^^^^^^^^^^^^^^^^^^^^^^^^^^^^^^^^^
  File "/home/airflow/.local/lib/python3.12/site-packages/airflow/models/taskinstance.py", line 3185, in _execute_task
    return _execute_task(self, context, task_orig)
           ^^^^^^^^^^^^^^^^^^^^^^^^^^^^^^^^^^^^^^^
  File "/home/airflow/.local/lib/python3.12/site-packages/airflow/models/taskinstance.py", line 768, in _execute_task
    result = _execute_callable(context=context, **execute_callable_kwargs)
             ^^^^^^^^^^^^^^^^^^^^^^^^^^^^^^^^^^^^^^^^^^^^^^^^^^^^^^^^^^^^^
  File "/home/airflow/.local/lib/python3.12/site-packages/airflow/models/taskinstance.py", line 734, in _execute_callable
    return ExecutionCallableRunner(
           ^^^^^^^^^^^^^^^^^^^^^^^^
  File "/home/airflow/.local/lib/python3.12/site-packages/airflow/utils/operator_helpers.py", line 252, in run
    return self.func(*args, **kwargs)
           ^^^^^^^^^^^^^^^^^^^^^^^^^^
  File "/home/airflow/.local/lib/python3.12/site-packages/airflow/models/baseoperator.py", line 424, in wrapper
    return func(self, *args, **kwargs)
           ^^^^^^^^^^^^^^^^^^^^^^^^^^^
  File "/home/airflow/.local/lib/python3.12/site-packages/airflow/operators/python.py", line 238, in execute
    return_value = self.execute_callable()
                   ^^^^^^^^^^^^^^^^^^^^^^^
  File "/home/airflow/.local/lib/python3.12/site-packages/airflow/operators/python.py", line 256, in execute_callable
    return runner.run(*self.op_args, **self.op_kwargs)
           ^^^^^^^^^^^^^^^^^^^^^^^^^^^^^^^^^^^^^^^^^^^
  File "/home/airflow/.local/lib/python3.12/site-packages/airflow/utils/operator_helpers.py", line 252, in run
    return self.func(*args, **kwargs)
           ^^^^^^^^^^^^^^^^^^^^^^^^^^
  File "/opt/airflow/dags/utils/ingest_data.py", line 37, in get_data
    conn = pg_connection()
           ^^^^^^^^^^^^^^^
  File "/opt/airflow/dags/utils/ingest_data.py", line 9, in pg_connection
    pg_user = Variable.get("PG_USER")
              ^^^^^^^^^^^^^^^^^^^^^^^
  File "/home/airflow/.local/lib/python3.12/site-packages/airflow/models/variable.py", line 145, in get
    raise KeyError(f"Variable {key} does not exist")
KeyError: 'Variable PG_USER does not exist'
[2025-04-18T17:14:16.261+0000] {local_task_job_runner.py:266} INFO - Task exited with return code 1
[2025-04-18T17:14:16.286+0000] {taskinstance.py:3901} INFO - 0 downstream tasks scheduled from follow-on schedule check
[2025-04-18T17:14:16.290+0000] {local_task_job_runner.py:245} INFO - ::endgroup::
